[2025-03-11T13:19:55.137+0000] {taskinstance.py:1103} INFO - Dependencies all met for dep_context=non-requeueable deps ti=<TaskInstance: csv_etl_pipeline.load_task manual__2025-03-11T13:19:47.769817+00:00 [queued]>
[2025-03-11T13:19:55.145+0000] {taskinstance.py:1103} INFO - Dependencies all met for dep_context=requeueable deps ti=<TaskInstance: csv_etl_pipeline.load_task manual__2025-03-11T13:19:47.769817+00:00 [queued]>
[2025-03-11T13:19:55.145+0000] {taskinstance.py:1308} INFO - Starting attempt 1 of 1
[2025-03-11T13:19:55.176+0000] {taskinstance.py:1327} INFO - Executing <Task(PythonOperator): load_task> on 2025-03-11 13:19:47.769817+00:00
[2025-03-11T13:19:55.183+0000] {standard_task_runner.py:57} INFO - Started process 154 to run task
[2025-03-11T13:19:55.186+0000] {standard_task_runner.py:84} INFO - Running: ['***', 'tasks', 'run', 'csv_etl_pipeline', 'load_task', 'manual__2025-03-11T13:19:47.769817+00:00', '--job-id', '51', '--raw', '--subdir', 'DAGS_FOLDER/etl.py', '--cfg-path', '/tmp/tmpswuexfr8']
[2025-03-11T13:19:55.187+0000] {standard_task_runner.py:85} INFO - Job 51: Subtask load_task
[2025-03-11T13:19:55.243+0000] {task_command.py:410} INFO - Running <TaskInstance: csv_etl_pipeline.load_task manual__2025-03-11T13:19:47.769817+00:00 [running]> on host 72a7cd2d8042
[2025-03-11T13:19:55.335+0000] {taskinstance.py:1547} INFO - Exporting env vars: AIRFLOW_CTX_DAG_OWNER='***' AIRFLOW_CTX_DAG_ID='csv_etl_pipeline' AIRFLOW_CTX_TASK_ID='load_task' AIRFLOW_CTX_EXECUTION_DATE='2025-03-11T13:19:47.769817+00:00' AIRFLOW_CTX_TRY_NUMBER='1' AIRFLOW_CTX_DAG_RUN_ID='manual__2025-03-11T13:19:47.769817+00:00'
[2025-03-11T13:19:55.366+0000] {logging_mixin.py:149} INFO - ✅ Données chargées dans output_data.csv
[2025-03-11T13:19:56.313+0000] {taskinstance.py:1824} ERROR - Task failed with exception
Traceback (most recent call last):
  File "/home/airflow/.local/lib/python3.7/site-packages/airflow/operators/python.py", line 181, in execute
    return_value = self.execute_callable()
  File "/home/airflow/.local/lib/python3.7/site-packages/airflow/operators/python.py", line 198, in execute_callable
    return self.python_callable(*self.op_args, **self.op_kwargs)
  File "/opt/airflow/dags/etl.py", line 48, in load_data
    port="5432"
  File "/home/airflow/.local/lib/python3.7/site-packages/psycopg2/__init__.py", line 122, in connect
    conn = _connect(dsn, connection_factory=connection_factory, **kwasync)
psycopg2.OperationalError: connection to server at "dpg-cv7vjfhu0jms73c6hgt0-a.frankfurt-postgres.render.com" (3.65.142.85), port 5432 failed: FATAL:  password authentication failed for user "***"
connection to server at "dpg-cv7vjfhu0jms73c6hgt0-a.frankfurt-postgres.render.com" (3.65.142.85), port 5432 failed: FATAL:  SSL/TLS required

[2025-03-11T13:19:56.324+0000] {taskinstance.py:1350} INFO - Marking task as FAILED. dag_id=csv_etl_pipeline, task_id=load_task, execution_date=20250311T131947, start_date=20250311T131955, end_date=20250311T131956
[2025-03-11T13:19:56.338+0000] {standard_task_runner.py:109} ERROR - Failed to execute job 51 for task load_task (connection to server at "dpg-cv7vjfhu0jms73c6hgt0-a.frankfurt-postgres.render.com" (3.65.142.85), port 5432 failed: FATAL:  password authentication failed for user "***"
connection to server at "dpg-cv7vjfhu0jms73c6hgt0-a.frankfurt-postgres.render.com" (3.65.142.85), port 5432 failed: FATAL:  SSL/TLS required
; 154)
[2025-03-11T13:19:56.362+0000] {local_task_job_runner.py:225} INFO - Task exited with return code 1
[2025-03-11T13:19:56.382+0000] {taskinstance.py:2651} INFO - 0 downstream tasks scheduled from follow-on schedule check
