[2025-03-11T14:28:09.836+0000] {taskinstance.py:1103} INFO - Dependencies all met for dep_context=non-requeueable deps ti=<TaskInstance: csv_etl.wait_for_file manual__2025-03-11T14:28:08.027194+00:00 [queued]>
[2025-03-11T14:28:09.851+0000] {taskinstance.py:1103} INFO - Dependencies all met for dep_context=requeueable deps ti=<TaskInstance: csv_etl.wait_for_file manual__2025-03-11T14:28:08.027194+00:00 [queued]>
[2025-03-11T14:28:09.851+0000] {taskinstance.py:1308} INFO - Starting attempt 1 of 1
[2025-03-11T14:28:09.879+0000] {taskinstance.py:1327} INFO - Executing <Task(PythonSensor): wait_for_file> on 2025-03-11 14:28:08.027194+00:00
[2025-03-11T14:28:09.889+0000] {standard_task_runner.py:57} INFO - Started process 1557 to run task
[2025-03-11T14:28:09.896+0000] {standard_task_runner.py:84} INFO - Running: ['***', 'tasks', 'run', 'csv_etl', 'wait_for_file', 'manual__2025-03-11T14:28:08.027194+00:00', '--job-id', '131', '--raw', '--subdir', 'DAGS_FOLDER/etl2.py', '--cfg-path', '/tmp/tmpbz8scurb']
[2025-03-11T14:28:09.896+0000] {standard_task_runner.py:85} INFO - Job 131: Subtask wait_for_file
[2025-03-11T14:28:09.986+0000] {task_command.py:410} INFO - Running <TaskInstance: csv_etl.wait_for_file manual__2025-03-11T14:28:08.027194+00:00 [running]> on host 72a7cd2d8042
[2025-03-11T14:28:10.116+0000] {taskinstance.py:1547} INFO - Exporting env vars: AIRFLOW_CTX_DAG_OWNER='***' AIRFLOW_CTX_DAG_ID='csv_etl' AIRFLOW_CTX_TASK_ID='wait_for_file' AIRFLOW_CTX_EXECUTION_DATE='2025-03-11T14:28:08.027194+00:00' AIRFLOW_CTX_TRY_NUMBER='1' AIRFLOW_CTX_DAG_RUN_ID='manual__2025-03-11T14:28:08.027194+00:00'
[2025-03-11T14:28:10.140+0000] {python.py:72} INFO - Poking callable: <function check_file_modified at 0x7f4d08d674d0>
[2025-03-11T14:28:10.141+0000] {taskinstance.py:1824} ERROR - Task failed with exception
Traceback (most recent call last):
  File "/home/airflow/.local/lib/python3.7/site-packages/airflow/sensors/base.py", line 242, in execute
    raise AirflowSensorTimeout(message)
airflow.exceptions.AirflowSensorTimeout: Sensor has timed out; run duration of 0.000991 seconds exceeds the specified timeout of 0.
[2025-03-11T14:28:10.154+0000] {taskinstance.py:1350} INFO - Immediate failure requested. Marking task as FAILED. dag_id=csv_etl, task_id=wait_for_file, execution_date=20250311T142808, start_date=20250311T142809, end_date=20250311T142810
[2025-03-11T14:28:10.173+0000] {standard_task_runner.py:109} ERROR - Failed to execute job 131 for task wait_for_file (Sensor has timed out; run duration of 0.000991 seconds exceeds the specified timeout of 0.; 1557)
[2025-03-11T14:28:10.187+0000] {local_task_job_runner.py:225} INFO - Task exited with return code 1
[2025-03-11T14:28:10.227+0000] {taskinstance.py:2651} INFO - 0 downstream tasks scheduled from follow-on schedule check
