[2025-05-05T09:44:52.268+0000] {taskinstance.py:1103} INFO - Dependencies all met for dep_context=non-requeueable deps ti=<TaskInstance: csv_etl_pipeline.load_task manual__2025-05-05T09:44:44.550347+00:00 [queued]>
[2025-05-05T09:44:52.277+0000] {taskinstance.py:1103} INFO - Dependencies all met for dep_context=requeueable deps ti=<TaskInstance: csv_etl_pipeline.load_task manual__2025-05-05T09:44:44.550347+00:00 [queued]>
[2025-05-05T09:44:52.278+0000] {taskinstance.py:1308} INFO - Starting attempt 1 of 1
[2025-05-05T09:44:52.291+0000] {taskinstance.py:1327} INFO - Executing <Task(PythonOperator): load_task> on 2025-05-05 09:44:44.550347+00:00
[2025-05-05T09:44:52.299+0000] {standard_task_runner.py:57} INFO - Started process 91 to run task
[2025-05-05T09:44:52.303+0000] {standard_task_runner.py:84} INFO - Running: ['***', 'tasks', 'run', 'csv_etl_pipeline', 'load_task', 'manual__2025-05-05T09:44:44.550347+00:00', '--job-id', '27', '--raw', '--subdir', 'DAGS_FOLDER/etl.py', '--cfg-path', '/tmp/tmpf2ag_a_5']
[2025-05-05T09:44:52.304+0000] {standard_task_runner.py:85} INFO - Job 27: Subtask load_task
[2025-05-05T09:44:52.353+0000] {task_command.py:410} INFO - Running <TaskInstance: csv_etl_pipeline.load_task manual__2025-05-05T09:44:44.550347+00:00 [running]> on host f4e282c83d8e
[2025-05-05T09:44:52.431+0000] {taskinstance.py:1547} INFO - Exporting env vars: AIRFLOW_CTX_DAG_OWNER='***' AIRFLOW_CTX_DAG_ID='csv_etl_pipeline' AIRFLOW_CTX_TASK_ID='load_task' AIRFLOW_CTX_EXECUTION_DATE='2025-05-05T09:44:44.550347+00:00' AIRFLOW_CTX_TRY_NUMBER='1' AIRFLOW_CTX_DAG_RUN_ID='manual__2025-05-05T09:44:44.550347+00:00'
[2025-05-05T09:44:52.582+0000] {logging_mixin.py:149} INFO - ✅ Données chargées dans output_data.csv
[2025-05-05T09:44:52.727+0000] {logging_mixin.py:149} INFO - ✅ Données insérées dans PostgreSQL
[2025-05-05T09:44:52.728+0000] {taskinstance.py:1824} ERROR - Task failed with exception
Traceback (most recent call last):
  File "/home/airflow/.local/lib/python3.7/site-packages/airflow/operators/python.py", line 181, in execute
    return_value = self.execute_callable()
  File "/home/airflow/.local/lib/python3.7/site-packages/airflow/operators/python.py", line 198, in execute_callable
    return self.python_callable(*self.op_args, **self.op_kwargs)
  File "/opt/airflow/dags/etl.py", line 52, in load_data
    os.remove(INPUT_CSV)
PermissionError: [Errno 13] Permission denied: '/opt/airflow/dags/data/fact_resultats_epreuves.csv'
[2025-05-05T09:44:52.742+0000] {taskinstance.py:1350} INFO - Marking task as FAILED. dag_id=csv_etl_pipeline, task_id=load_task, execution_date=20250505T094444, start_date=20250505T094452, end_date=20250505T094452
[2025-05-05T09:44:52.773+0000] {standard_task_runner.py:109} ERROR - Failed to execute job 27 for task load_task ([Errno 13] Permission denied: '/opt/airflow/dags/data/fact_resultats_epreuves.csv'; 91)
[2025-05-05T09:44:52.796+0000] {local_task_job_runner.py:225} INFO - Task exited with return code 1
[2025-05-05T09:44:52.825+0000] {taskinstance.py:2651} INFO - 0 downstream tasks scheduled from follow-on schedule check
