[2025-03-11T11:17:19.108+0000] {taskinstance.py:1103} INFO - Dependencies all met for dep_context=non-requeueable deps ti=<TaskInstance: csv_etl_pipeline.load_task manual__2025-03-11T11:17:12.794252+00:00 [queued]>
[2025-03-11T11:17:19.119+0000] {taskinstance.py:1103} INFO - Dependencies all met for dep_context=requeueable deps ti=<TaskInstance: csv_etl_pipeline.load_task manual__2025-03-11T11:17:12.794252+00:00 [queued]>
[2025-03-11T11:17:19.119+0000] {taskinstance.py:1308} INFO - Starting attempt 1 of 1
[2025-03-11T11:17:19.134+0000] {taskinstance.py:1327} INFO - Executing <Task(PythonOperator): load_task> on 2025-03-11 11:17:12.794252+00:00
[2025-03-11T11:17:19.142+0000] {standard_task_runner.py:57} INFO - Started process 710 to run task
[2025-03-11T11:17:19.146+0000] {standard_task_runner.py:84} INFO - Running: ['***', 'tasks', 'run', 'csv_etl_pipeline', 'load_task', 'manual__2025-03-11T11:17:12.794252+00:00', '--job-id', '34', '--raw', '--subdir', 'DAGS_FOLDER/etl.py', '--cfg-path', '/tmp/tmph44x86jj']
[2025-03-11T11:17:19.147+0000] {standard_task_runner.py:85} INFO - Job 34: Subtask load_task
[2025-03-11T11:17:19.199+0000] {task_command.py:410} INFO - Running <TaskInstance: csv_etl_pipeline.load_task manual__2025-03-11T11:17:12.794252+00:00 [running]> on host 11da0919092a
[2025-03-11T11:17:19.301+0000] {taskinstance.py:1547} INFO - Exporting env vars: AIRFLOW_CTX_DAG_OWNER='***' AIRFLOW_CTX_DAG_ID='csv_etl_pipeline' AIRFLOW_CTX_TASK_ID='load_task' AIRFLOW_CTX_EXECUTION_DATE='2025-03-11T11:17:12.794252+00:00' AIRFLOW_CTX_TRY_NUMBER='1' AIRFLOW_CTX_DAG_RUN_ID='manual__2025-03-11T11:17:12.794252+00:00'
[2025-03-11T11:17:19.531+0000] {logging_mixin.py:149} INFO - ✅ Données chargées dans output_data.csv
[2025-03-11T11:17:20.431+0000] {taskinstance.py:1824} ERROR - Task failed with exception
Traceback (most recent call last):
  File "/home/airflow/.local/lib/python3.7/site-packages/airflow/operators/python.py", line 181, in execute
    return_value = self.execute_callable()
  File "/home/airflow/.local/lib/python3.7/site-packages/airflow/operators/python.py", line 198, in execute_callable
    return self.python_callable(*self.op_args, **self.op_kwargs)
  File "/opt/airflow/dags/etl.py", line 72, in load_data
    insert_data(df)
  File "/opt/airflow/dags/etl.py", line 69, in insert_data
    ''', (row["Id_vente"], row["Date_transaction"], row["Valeur"], row["Id_bien"]))
psycopg2.errors.UndefinedColumn: column "id_vente" of relation "weather" does not exist
LINE 2:                 INSERT INTO weather (Id_vente, Date_transact...
                                             ^

[2025-03-11T11:17:20.443+0000] {taskinstance.py:1350} INFO - Marking task as FAILED. dag_id=csv_etl_pipeline, task_id=load_task, execution_date=20250311T111712, start_date=20250311T111719, end_date=20250311T111720
[2025-03-11T11:17:20.467+0000] {standard_task_runner.py:109} ERROR - Failed to execute job 34 for task load_task (column "id_vente" of relation "weather" does not exist
LINE 2:                 INSERT INTO weather (Id_vente, Date_transact...
                                             ^
; 710)
[2025-03-11T11:17:20.485+0000] {local_task_job_runner.py:225} INFO - Task exited with return code 1
[2025-03-11T11:17:20.511+0000] {taskinstance.py:2651} INFO - 0 downstream tasks scheduled from follow-on schedule check
