[2025-03-11T10:46:16.928+0000] {taskinstance.py:1103} INFO - Dependencies all met for dep_context=non-requeueable deps ti=<TaskInstance: csv_etl_pipeline.transform_task manual__2025-03-11T10:46:12.551111+00:00 [queued]>
[2025-03-11T10:46:17.168+0000] {taskinstance.py:1103} INFO - Dependencies all met for dep_context=requeueable deps ti=<TaskInstance: csv_etl_pipeline.transform_task manual__2025-03-11T10:46:12.551111+00:00 [queued]>
[2025-03-11T10:46:17.168+0000] {taskinstance.py:1308} INFO - Starting attempt 1 of 1
[2025-03-11T10:46:17.191+0000] {taskinstance.py:1327} INFO - Executing <Task(PythonOperator): transform_task> on 2025-03-11 10:46:12.551111+00:00
[2025-03-11T10:46:17.200+0000] {standard_task_runner.py:57} INFO - Started process 125 to run task
[2025-03-11T10:46:17.206+0000] {standard_task_runner.py:84} INFO - Running: ['***', 'tasks', 'run', 'csv_etl_pipeline', 'transform_task', 'manual__2025-03-11T10:46:12.551111+00:00', '--job-id', '17', '--raw', '--subdir', 'DAGS_FOLDER/etl.py', '--cfg-path', '/tmp/tmprpjk843r']
[2025-03-11T10:46:17.207+0000] {standard_task_runner.py:85} INFO - Job 17: Subtask transform_task
[2025-03-11T10:46:17.299+0000] {task_command.py:410} INFO - Running <TaskInstance: csv_etl_pipeline.transform_task manual__2025-03-11T10:46:12.551111+00:00 [running]> on host 11da0919092a
[2025-03-11T10:46:17.440+0000] {taskinstance.py:1547} INFO - Exporting env vars: AIRFLOW_CTX_DAG_OWNER='***' AIRFLOW_CTX_DAG_ID='csv_etl_pipeline' AIRFLOW_CTX_TASK_ID='transform_task' AIRFLOW_CTX_EXECUTION_DATE='2025-03-11T10:46:12.551111+00:00' AIRFLOW_CTX_TRY_NUMBER='1' AIRFLOW_CTX_DAG_RUN_ID='manual__2025-03-11T10:46:12.551111+00:00'
[2025-03-11T10:46:17.787+0000] {taskinstance.py:1824} ERROR - Task failed with exception
Traceback (most recent call last):
  File "/home/airflow/.local/lib/python3.7/site-packages/pandas/core/indexes/base.py", line 3361, in get_loc
    return self._engine.get_loc(casted_key)
  File "pandas/_libs/index.pyx", line 76, in pandas._libs.index.IndexEngine.get_loc
  File "pandas/_libs/index.pyx", line 108, in pandas._libs.index.IndexEngine.get_loc
  File "pandas/_libs/hashtable_class_helper.pxi", line 5198, in pandas._libs.hashtable.PyObjectHashTable.get_item
  File "pandas/_libs/hashtable_class_helper.pxi", line 5206, in pandas._libs.hashtable.PyObjectHashTable.get_item
KeyError: 'price'

The above exception was the direct cause of the following exception:

Traceback (most recent call last):
  File "/home/airflow/.local/lib/python3.7/site-packages/airflow/operators/python.py", line 181, in execute
    return_value = self.execute_callable()
  File "/home/airflow/.local/lib/python3.7/site-packages/airflow/operators/python.py", line 198, in execute_callable
    return self.python_callable(*self.op_args, **self.op_kwargs)
  File "/opt/airflow/dags/etl.py", line 25, in transform_data
    df["price"] = df["price"].astype(float)
  File "/home/airflow/.local/lib/python3.7/site-packages/pandas/core/frame.py", line 3458, in __getitem__
    indexer = self.columns.get_loc(key)
  File "/home/airflow/.local/lib/python3.7/site-packages/pandas/core/indexes/base.py", line 3363, in get_loc
    raise KeyError(key) from err
KeyError: 'price'
[2025-03-11T10:46:17.806+0000] {taskinstance.py:1350} INFO - Marking task as FAILED. dag_id=csv_etl_pipeline, task_id=transform_task, execution_date=20250311T104612, start_date=20250311T104616, end_date=20250311T104617
[2025-03-11T10:46:17.828+0000] {standard_task_runner.py:109} ERROR - Failed to execute job 17 for task transform_task ('price'; 125)
[2025-03-11T10:46:17.859+0000] {local_task_job_runner.py:225} INFO - Task exited with return code 1
[2025-03-11T10:46:17.912+0000] {taskinstance.py:2651} INFO - 0 downstream tasks scheduled from follow-on schedule check
