[2025-05-05T09:31:39.123+0000] {taskinstance.py:1103} INFO - Dependencies all met for dep_context=non-requeueable deps ti=<TaskInstance: csv_etl_pipeline.load_task manual__2025-05-05T09:31:32.693079+00:00 [queued]>
[2025-05-05T09:31:39.132+0000] {taskinstance.py:1103} INFO - Dependencies all met for dep_context=requeueable deps ti=<TaskInstance: csv_etl_pipeline.load_task manual__2025-05-05T09:31:32.693079+00:00 [queued]>
[2025-05-05T09:31:39.133+0000] {taskinstance.py:1308} INFO - Starting attempt 1 of 1
[2025-05-05T09:31:39.146+0000] {taskinstance.py:1327} INFO - Executing <Task(PythonOperator): load_task> on 2025-05-05 09:31:32.693079+00:00
[2025-05-05T09:31:39.156+0000] {standard_task_runner.py:57} INFO - Started process 100 to run task
[2025-05-05T09:31:39.160+0000] {standard_task_runner.py:84} INFO - Running: ['***', 'tasks', 'run', 'csv_etl_pipeline', 'load_task', 'manual__2025-05-05T09:31:32.693079+00:00', '--job-id', '11', '--raw', '--subdir', 'DAGS_FOLDER/etl.py', '--cfg-path', '/tmp/tmpmm8wj8rd']
[2025-05-05T09:31:39.161+0000] {standard_task_runner.py:85} INFO - Job 11: Subtask load_task
[2025-05-05T09:31:39.210+0000] {task_command.py:410} INFO - Running <TaskInstance: csv_etl_pipeline.load_task manual__2025-05-05T09:31:32.693079+00:00 [running]> on host cd069ccd2246
[2025-05-05T09:31:39.289+0000] {taskinstance.py:1547} INFO - Exporting env vars: AIRFLOW_CTX_DAG_OWNER='***' AIRFLOW_CTX_DAG_ID='csv_etl_pipeline' AIRFLOW_CTX_TASK_ID='load_task' AIRFLOW_CTX_EXECUTION_DATE='2025-05-05T09:31:32.693079+00:00' AIRFLOW_CTX_TRY_NUMBER='1' AIRFLOW_CTX_DAG_RUN_ID='manual__2025-05-05T09:31:32.693079+00:00'
[2025-05-05T09:31:39.304+0000] {taskinstance.py:1824} ERROR - Task failed with exception
Traceback (most recent call last):
  File "/home/airflow/.local/lib/python3.7/site-packages/airflow/operators/python.py", line 181, in execute
    return_value = self.execute_callable()
  File "/home/airflow/.local/lib/python3.7/site-packages/airflow/operators/python.py", line 198, in execute_callable
    return self.python_callable(*self.op_args, **self.op_kwargs)
  File "/opt/airflow/dags/etl.py", line 39, in load_data
    df = pd.read_csv(data)
  File "/home/airflow/.local/lib/python3.7/site-packages/pandas/util/_decorators.py", line 311, in wrapper
    return func(*args, **kwargs)
  File "/home/airflow/.local/lib/python3.7/site-packages/pandas/io/parsers/readers.py", line 586, in read_csv
    return _read(filepath_or_buffer, kwds)
  File "/home/airflow/.local/lib/python3.7/site-packages/pandas/io/parsers/readers.py", line 482, in _read
    parser = TextFileReader(filepath_or_buffer, **kwds)
  File "/home/airflow/.local/lib/python3.7/site-packages/pandas/io/parsers/readers.py", line 811, in __init__
    self._engine = self._make_engine(self.engine)
  File "/home/airflow/.local/lib/python3.7/site-packages/pandas/io/parsers/readers.py", line 1040, in _make_engine
    return mapping[engine](self.f, **self.options)  # type: ignore[call-arg]
  File "/home/airflow/.local/lib/python3.7/site-packages/pandas/io/parsers/c_parser_wrapper.py", line 51, in __init__
    self._open_handles(src, kwds)
  File "/home/airflow/.local/lib/python3.7/site-packages/pandas/io/parsers/base_parser.py", line 229, in _open_handles
    errors=kwds.get("encoding_errors", "strict"),
  File "/home/airflow/.local/lib/python3.7/site-packages/pandas/io/common.py", line 614, in get_handle
    storage_options=storage_options,
  File "/home/airflow/.local/lib/python3.7/site-packages/pandas/io/common.py", line 396, in _get_filepath_or_buffer
    raise ValueError(msg)
ValueError: Invalid file path or buffer object type: <class 'NoneType'>
[2025-05-05T09:31:39.314+0000] {taskinstance.py:1350} INFO - Marking task as FAILED. dag_id=csv_etl_pipeline, task_id=load_task, execution_date=20250505T093132, start_date=20250505T093139, end_date=20250505T093139
[2025-05-05T09:31:39.324+0000] {standard_task_runner.py:109} ERROR - Failed to execute job 11 for task load_task (Invalid file path or buffer object type: <class 'NoneType'>; 100)
[2025-05-05T09:31:39.371+0000] {local_task_job_runner.py:225} INFO - Task exited with return code 1
[2025-05-05T09:31:39.403+0000] {taskinstance.py:2651} INFO - 0 downstream tasks scheduled from follow-on schedule check
