[2025-03-11T14:55:11.083+0000] {taskinstance.py:1103} INFO - Dependencies all met for dep_context=non-requeueable deps ti=<TaskInstance: csv_etl.transform_task manual__2025-03-11T14:55:07.179600+00:00 [queued]>
[2025-03-11T14:55:11.291+0000] {taskinstance.py:1103} INFO - Dependencies all met for dep_context=requeueable deps ti=<TaskInstance: csv_etl.transform_task manual__2025-03-11T14:55:07.179600+00:00 [queued]>
[2025-03-11T14:55:11.291+0000] {taskinstance.py:1308} INFO - Starting attempt 1 of 1
[2025-03-11T14:55:11.311+0000] {taskinstance.py:1327} INFO - Executing <Task(PythonOperator): transform_task> on 2025-03-11 14:55:07.179600+00:00
[2025-03-11T14:55:11.319+0000] {standard_task_runner.py:57} INFO - Started process 129 to run task
[2025-03-11T14:55:11.325+0000] {standard_task_runner.py:84} INFO - Running: ['***', 'tasks', 'run', 'csv_etl', 'transform_task', 'manual__2025-03-11T14:55:07.179600+00:00', '--job-id', '162', '--raw', '--subdir', 'DAGS_FOLDER/etl2.py', '--cfg-path', '/tmp/tmp28idx_sq']
[2025-03-11T14:55:11.326+0000] {standard_task_runner.py:85} INFO - Job 162: Subtask transform_task
[2025-03-11T14:55:11.402+0000] {task_command.py:410} INFO - Running <TaskInstance: csv_etl.transform_task manual__2025-03-11T14:55:07.179600+00:00 [running]> on host 72a7cd2d8042
[2025-03-11T14:55:11.508+0000] {taskinstance.py:1547} INFO - Exporting env vars: AIRFLOW_CTX_DAG_OWNER='***' AIRFLOW_CTX_DAG_ID='csv_etl' AIRFLOW_CTX_TASK_ID='transform_task' AIRFLOW_CTX_EXECUTION_DATE='2025-03-11T14:55:07.179600+00:00' AIRFLOW_CTX_TRY_NUMBER='1' AIRFLOW_CTX_DAG_RUN_ID='manual__2025-03-11T14:55:07.179600+00:00'
[2025-03-11T14:55:11.555+0000] {taskinstance.py:1824} ERROR - Task failed with exception
Traceback (most recent call last):
  File "/home/airflow/.local/lib/python3.7/site-packages/airflow/operators/python.py", line 181, in execute
    return_value = self.execute_callable()
  File "/home/airflow/.local/lib/python3.7/site-packages/airflow/operators/python.py", line 198, in execute_callable
    return self.python_callable(*self.op_args, **self.op_kwargs)
  File "/opt/airflow/dags/etl2.py", line 29, in transform_data
    df['Valeur'] = df['Valeur'].str.replace(',', '.')
  File "/home/airflow/.local/lib/python3.7/site-packages/pandas/core/generic.py", line 5487, in __getattr__
    return object.__getattribute__(self, name)
  File "/home/airflow/.local/lib/python3.7/site-packages/pandas/core/accessor.py", line 181, in __get__
    accessor_obj = self._accessor(obj)
  File "/home/airflow/.local/lib/python3.7/site-packages/pandas/core/strings/accessor.py", line 168, in __init__
    self._inferred_dtype = self._validate(data)
  File "/home/airflow/.local/lib/python3.7/site-packages/pandas/core/strings/accessor.py", line 225, in _validate
    raise AttributeError("Can only use .str accessor with string values!")
AttributeError: Can only use .str accessor with string values!
[2025-03-11T14:55:11.582+0000] {taskinstance.py:1350} INFO - Marking task as FAILED. dag_id=csv_etl, task_id=transform_task, execution_date=20250311T145507, start_date=20250311T145511, end_date=20250311T145511
[2025-03-11T14:55:11.600+0000] {standard_task_runner.py:109} ERROR - Failed to execute job 162 for task transform_task (Can only use .str accessor with string values!; 129)
[2025-03-11T14:55:11.617+0000] {local_task_job_runner.py:225} INFO - Task exited with return code 1
[2025-03-11T14:55:11.650+0000] {taskinstance.py:2651} INFO - 0 downstream tasks scheduled from follow-on schedule check
