[2025-03-11T14:53:41.713+0000] {taskinstance.py:1103} INFO - Dependencies all met for dep_context=non-requeueable deps ti=<TaskInstance: file_watcher_dag.trigger_main_dag manual__2025-03-11T14:53:36.666715+00:00 [queued]>
[2025-03-11T14:53:41.721+0000] {taskinstance.py:1103} INFO - Dependencies all met for dep_context=requeueable deps ti=<TaskInstance: file_watcher_dag.trigger_main_dag manual__2025-03-11T14:53:36.666715+00:00 [queued]>
[2025-03-11T14:53:41.721+0000] {taskinstance.py:1308} INFO - Starting attempt 1 of 1
[2025-03-11T14:53:41.733+0000] {taskinstance.py:1327} INFO - Executing <Task(TriggerDagRunOperator): trigger_main_dag> on 2025-03-11 14:53:36.666715+00:00
[2025-03-11T14:53:41.738+0000] {standard_task_runner.py:57} INFO - Started process 90 to run task
[2025-03-11T14:53:41.742+0000] {standard_task_runner.py:84} INFO - Running: ['***', 'tasks', 'run', 'file_watcher_dag', 'trigger_main_dag', 'manual__2025-03-11T14:53:36.666715+00:00', '--job-id', '158', '--raw', '--subdir', 'DAGS_FOLDER/watch.py', '--cfg-path', '/tmp/tmpv8t41tk0']
[2025-03-11T14:53:41.744+0000] {standard_task_runner.py:85} INFO - Job 158: Subtask trigger_main_dag
[2025-03-11T14:53:41.790+0000] {task_command.py:410} INFO - Running <TaskInstance: file_watcher_dag.trigger_main_dag manual__2025-03-11T14:53:36.666715+00:00 [running]> on host 72a7cd2d8042
[2025-03-11T14:53:41.868+0000] {taskinstance.py:1547} INFO - Exporting env vars: AIRFLOW_CTX_DAG_OWNER='***' AIRFLOW_CTX_DAG_ID='file_watcher_dag' AIRFLOW_CTX_TASK_ID='trigger_main_dag' AIRFLOW_CTX_EXECUTION_DATE='2025-03-11T14:53:36.666715+00:00' AIRFLOW_CTX_TRY_NUMBER='1' AIRFLOW_CTX_DAG_RUN_ID='manual__2025-03-11T14:53:36.666715+00:00'
[2025-03-11T14:53:41.886+0000] {taskinstance.py:1824} ERROR - Task failed with exception
Traceback (most recent call last):
  File "/home/airflow/.local/lib/python3.7/site-packages/airflow/operators/trigger_dagrun.py", line 155, in execute
    replace_microseconds=False,
  File "/home/airflow/.local/lib/python3.7/site-packages/airflow/api/common/trigger_dag.py", line 119, in trigger_dag
    raise DagNotFound(f"Dag id {dag_id} not found in DagModel")
airflow.exceptions.DagNotFound: Dag id etl2 not found in DagModel
[2025-03-11T14:53:41.890+0000] {taskinstance.py:1350} INFO - Marking task as FAILED. dag_id=file_watcher_dag, task_id=trigger_main_dag, execution_date=20250311T145336, start_date=20250311T145341, end_date=20250311T145341
[2025-03-11T14:53:41.900+0000] {standard_task_runner.py:109} ERROR - Failed to execute job 158 for task trigger_main_dag (Dag id etl2 not found in DagModel; 90)
[2025-03-11T14:53:41.913+0000] {local_task_job_runner.py:225} INFO - Task exited with return code 1
[2025-03-11T14:53:41.929+0000] {taskinstance.py:2651} INFO - 0 downstream tasks scheduled from follow-on schedule check
