[2025-03-11T13:23:28.955+0000] {taskinstance.py:1103} INFO - Dependencies all met for dep_context=non-requeueable deps ti=<TaskInstance: csv_etl_pipeline.load_task manual__2025-03-11T13:23:23.133456+00:00 [queued]>
[2025-03-11T13:23:28.965+0000] {taskinstance.py:1103} INFO - Dependencies all met for dep_context=requeueable deps ti=<TaskInstance: csv_etl_pipeline.load_task manual__2025-03-11T13:23:23.133456+00:00 [queued]>
[2025-03-11T13:23:28.965+0000] {taskinstance.py:1308} INFO - Starting attempt 1 of 1
[2025-03-11T13:23:28.982+0000] {taskinstance.py:1327} INFO - Executing <Task(PythonOperator): load_task> on 2025-03-11 13:23:23.133456+00:00
[2025-03-11T13:23:28.990+0000] {standard_task_runner.py:57} INFO - Started process 226 to run task
[2025-03-11T13:23:28.994+0000] {standard_task_runner.py:84} INFO - Running: ['***', 'tasks', 'run', 'csv_etl_pipeline', 'load_task', 'manual__2025-03-11T13:23:23.133456+00:00', '--job-id', '57', '--raw', '--subdir', 'DAGS_FOLDER/etl.py', '--cfg-path', '/tmp/tmplsetlg9t']
[2025-03-11T13:23:28.995+0000] {standard_task_runner.py:85} INFO - Job 57: Subtask load_task
[2025-03-11T13:23:29.051+0000] {task_command.py:410} INFO - Running <TaskInstance: csv_etl_pipeline.load_task manual__2025-03-11T13:23:23.133456+00:00 [running]> on host 72a7cd2d8042
[2025-03-11T13:23:29.161+0000] {taskinstance.py:1547} INFO - Exporting env vars: AIRFLOW_CTX_DAG_OWNER='***' AIRFLOW_CTX_DAG_ID='csv_etl_pipeline' AIRFLOW_CTX_TASK_ID='load_task' AIRFLOW_CTX_EXECUTION_DATE='2025-03-11T13:23:23.133456+00:00' AIRFLOW_CTX_TRY_NUMBER='1' AIRFLOW_CTX_DAG_RUN_ID='manual__2025-03-11T13:23:23.133456+00:00'
[2025-03-11T13:23:29.199+0000] {logging_mixin.py:149} INFO - ✅ Données chargées dans output_data.csv
[2025-03-11T13:23:29.200+0000] {taskinstance.py:1824} ERROR - Task failed with exception
Traceback (most recent call last):
  File "/home/airflow/.local/lib/python3.7/site-packages/airflow/operators/python.py", line 181, in execute
    return_value = self.execute_callable()
  File "/home/airflow/.local/lib/python3.7/site-packages/airflow/operators/python.py", line 198, in execute_callable
    return self.python_callable(*self.op_args, **self.op_kwargs)
  File "/opt/airflow/dags/etl.py", line 48, in load_data
    port        = "5432"
  File "/home/airflow/.local/lib/python3.7/site-packages/psycopg2/__init__.py", line 122, in connect
    conn = _connect(dsn, connection_factory=connection_factory, **kwasync)
psycopg2.OperationalError: connection to server at "localhost" (::1), port 5432 failed: Connection refused
	Is the server running on that host and accepting TCP/IP connections?
connection to server at "localhost" (127.0.0.1), port 5432 failed: Connection refused
	Is the server running on that host and accepting TCP/IP connections?

[2025-03-11T13:23:29.211+0000] {taskinstance.py:1350} INFO - Marking task as FAILED. dag_id=csv_etl_pipeline, task_id=load_task, execution_date=20250311T132323, start_date=20250311T132328, end_date=20250311T132329
[2025-03-11T13:23:29.227+0000] {standard_task_runner.py:109} ERROR - Failed to execute job 57 for task load_task (connection to server at "localhost" (::1), port 5432 failed: Connection refused
	Is the server running on that host and accepting TCP/IP connections?
connection to server at "localhost" (127.0.0.1), port 5432 failed: Connection refused
	Is the server running on that host and accepting TCP/IP connections?
; 226)
[2025-03-11T13:23:29.246+0000] {local_task_job_runner.py:225} INFO - Task exited with return code 1
[2025-03-11T13:23:29.268+0000] {taskinstance.py:2651} INFO - 0 downstream tasks scheduled from follow-on schedule check
