[2025-03-11T13:21:26.668+0000] {taskinstance.py:1103} INFO - Dependencies all met for dep_context=non-requeueable deps ti=<TaskInstance: csv_etl_pipeline.load_task manual__2025-03-11T13:21:20.704590+00:00 [queued]>
[2025-03-11T13:21:26.681+0000] {taskinstance.py:1103} INFO - Dependencies all met for dep_context=requeueable deps ti=<TaskInstance: csv_etl_pipeline.load_task manual__2025-03-11T13:21:20.704590+00:00 [queued]>
[2025-03-11T13:21:26.681+0000] {taskinstance.py:1308} INFO - Starting attempt 1 of 1
[2025-03-11T13:21:26.702+0000] {taskinstance.py:1327} INFO - Executing <Task(PythonOperator): load_task> on 2025-03-11 13:21:20.704590+00:00
[2025-03-11T13:21:26.710+0000] {standard_task_runner.py:57} INFO - Started process 190 to run task
[2025-03-11T13:21:26.716+0000] {standard_task_runner.py:84} INFO - Running: ['***', 'tasks', 'run', 'csv_etl_pipeline', 'load_task', 'manual__2025-03-11T13:21:20.704590+00:00', '--job-id', '54', '--raw', '--subdir', 'DAGS_FOLDER/etl.py', '--cfg-path', '/tmp/tmprmig5f9z']
[2025-03-11T13:21:26.717+0000] {standard_task_runner.py:85} INFO - Job 54: Subtask load_task
[2025-03-11T13:21:26.788+0000] {task_command.py:410} INFO - Running <TaskInstance: csv_etl_pipeline.load_task manual__2025-03-11T13:21:20.704590+00:00 [running]> on host 72a7cd2d8042
[2025-03-11T13:21:26.903+0000] {taskinstance.py:1547} INFO - Exporting env vars: AIRFLOW_CTX_DAG_OWNER='***' AIRFLOW_CTX_DAG_ID='csv_etl_pipeline' AIRFLOW_CTX_TASK_ID='load_task' AIRFLOW_CTX_EXECUTION_DATE='2025-03-11T13:21:20.704590+00:00' AIRFLOW_CTX_TRY_NUMBER='1' AIRFLOW_CTX_DAG_RUN_ID='manual__2025-03-11T13:21:20.704590+00:00'
[2025-03-11T13:21:26.939+0000] {logging_mixin.py:149} INFO - ✅ Données chargées dans output_data.csv
[2025-03-11T13:21:26.939+0000] {taskinstance.py:1824} ERROR - Task failed with exception
Traceback (most recent call last):
  File "/home/airflow/.local/lib/python3.7/site-packages/airflow/operators/python.py", line 181, in execute
    return_value = self.execute_callable()
  File "/home/airflow/.local/lib/python3.7/site-packages/airflow/operators/python.py", line 198, in execute_callable
    return self.python_callable(*self.op_args, **self.op_kwargs)
  File "/opt/airflow/dags/etl.py", line 48, in load_data
    port="5432"
  File "/home/airflow/.local/lib/python3.7/site-packages/psycopg2/__init__.py", line 122, in connect
    conn = _connect(dsn, connection_factory=connection_factory, **kwasync)
psycopg2.OperationalError: could not translate host name "jdbc:postgresql://localhost:5432/" to address: Name or service not known

[2025-03-11T13:21:26.950+0000] {taskinstance.py:1350} INFO - Marking task as FAILED. dag_id=csv_etl_pipeline, task_id=load_task, execution_date=20250311T132120, start_date=20250311T132126, end_date=20250311T132126
[2025-03-11T13:21:26.965+0000] {standard_task_runner.py:109} ERROR - Failed to execute job 54 for task load_task (could not translate host name "jdbc:postgresql://localhost:5432/" to address: Name or service not known
; 190)
[2025-03-11T13:21:27.008+0000] {local_task_job_runner.py:225} INFO - Task exited with return code 1
[2025-03-11T13:21:27.042+0000] {taskinstance.py:2651} INFO - 0 downstream tasks scheduled from follow-on schedule check
