[2025-03-11T10:47:43.033+0000] {taskinstance.py:1103} INFO - Dependencies all met for dep_context=non-requeueable deps ti=<TaskInstance: csv_etl_pipeline.load_task manual__2025-03-11T10:47:36.736852+00:00 [queued]>
[2025-03-11T10:47:43.180+0000] {taskinstance.py:1103} INFO - Dependencies all met for dep_context=requeueable deps ti=<TaskInstance: csv_etl_pipeline.load_task manual__2025-03-11T10:47:36.736852+00:00 [queued]>
[2025-03-11T10:47:43.180+0000] {taskinstance.py:1308} INFO - Starting attempt 1 of 1
[2025-03-11T10:47:43.194+0000] {taskinstance.py:1327} INFO - Executing <Task(PythonOperator): load_task> on 2025-03-11 10:47:36.736852+00:00
[2025-03-11T10:47:43.201+0000] {standard_task_runner.py:57} INFO - Started process 167 to run task
[2025-03-11T10:47:43.205+0000] {standard_task_runner.py:84} INFO - Running: ['***', 'tasks', 'run', 'csv_etl_pipeline', 'load_task', 'manual__2025-03-11T10:47:36.736852+00:00', '--job-id', '22', '--raw', '--subdir', 'DAGS_FOLDER/etl.py', '--cfg-path', '/tmp/tmpod2rmaru']
[2025-03-11T10:47:43.206+0000] {standard_task_runner.py:85} INFO - Job 22: Subtask load_task
[2025-03-11T10:47:43.259+0000] {task_command.py:410} INFO - Running <TaskInstance: csv_etl_pipeline.load_task manual__2025-03-11T10:47:36.736852+00:00 [running]> on host 11da0919092a
[2025-03-11T10:47:43.338+0000] {taskinstance.py:1547} INFO - Exporting env vars: AIRFLOW_CTX_DAG_OWNER='***' AIRFLOW_CTX_DAG_ID='csv_etl_pipeline' AIRFLOW_CTX_TASK_ID='load_task' AIRFLOW_CTX_EXECUTION_DATE='2025-03-11T10:47:36.736852+00:00' AIRFLOW_CTX_TRY_NUMBER='1' AIRFLOW_CTX_DAG_RUN_ID='manual__2025-03-11T10:47:36.736852+00:00'
[2025-03-11T10:47:43.507+0000] {taskinstance.py:1824} ERROR - Task failed with exception
Traceback (most recent call last):
  File "/home/airflow/.local/lib/python3.7/site-packages/airflow/operators/python.py", line 181, in execute
    return_value = self.execute_callable()
  File "/home/airflow/.local/lib/python3.7/site-packages/airflow/operators/python.py", line 198, in execute_callable
    return self.python_callable(*self.op_args, **self.op_kwargs)
  File "/opt/airflow/dags/etl.py", line 37, in load_data
    df.to_csv(OUTPUT_CSV, index=False)
  File "/home/airflow/.local/lib/python3.7/site-packages/pandas/core/generic.py", line 3482, in to_csv
    storage_options=storage_options,
  File "/home/airflow/.local/lib/python3.7/site-packages/pandas/io/formats/format.py", line 1105, in to_csv
    csv_formatter.save()
  File "/home/airflow/.local/lib/python3.7/site-packages/pandas/io/formats/csvs.py", line 243, in save
    storage_options=self.storage_options,
  File "/home/airflow/.local/lib/python3.7/site-packages/pandas/io/common.py", line 707, in get_handle
    newline="",
FileNotFoundError: [Errno 2] No such file or directory: 'opt/airflow/dags/data/output_data.csv'
[2025-03-11T10:47:43.517+0000] {taskinstance.py:1350} INFO - Marking task as FAILED. dag_id=csv_etl_pipeline, task_id=load_task, execution_date=20250311T104736, start_date=20250311T104743, end_date=20250311T104743
[2025-03-11T10:47:43.528+0000] {standard_task_runner.py:109} ERROR - Failed to execute job 22 for task load_task ([Errno 2] No such file or directory: 'opt/airflow/dags/data/output_data.csv'; 167)
[2025-03-11T10:47:43.537+0000] {local_task_job_runner.py:225} INFO - Task exited with return code 1
[2025-03-11T10:47:43.554+0000] {taskinstance.py:2651} INFO - 0 downstream tasks scheduled from follow-on schedule check
