[2025-03-11T14:23:34.897+0000] {taskinstance.py:1103} INFO - Dependencies all met for dep_context=non-requeueable deps ti=<TaskInstance: csv_etl_pipeline.wait_for_file manual__2025-03-11T14:23:32.722483+00:00 [queued]>
[2025-03-11T14:23:34.914+0000] {taskinstance.py:1103} INFO - Dependencies all met for dep_context=requeueable deps ti=<TaskInstance: csv_etl_pipeline.wait_for_file manual__2025-03-11T14:23:32.722483+00:00 [queued]>
[2025-03-11T14:23:34.914+0000] {taskinstance.py:1308} INFO - Starting attempt 1 of 1
[2025-03-11T14:23:34.951+0000] {taskinstance.py:1327} INFO - Executing <Task(FileSensor): wait_for_file> on 2025-03-11 14:23:32.722483+00:00
[2025-03-11T14:23:34.969+0000] {standard_task_runner.py:57} INFO - Started process 1470 to run task
[2025-03-11T14:23:34.979+0000] {standard_task_runner.py:84} INFO - Running: ['***', 'tasks', 'run', 'csv_etl_pipeline', 'wait_for_file', 'manual__2025-03-11T14:23:32.722483+00:00', '--job-id', '126', '--raw', '--subdir', 'DAGS_FOLDER/etl.py', '--cfg-path', '/tmp/tmpysu7c19w']
[2025-03-11T14:23:34.981+0000] {standard_task_runner.py:85} INFO - Job 126: Subtask wait_for_file
[2025-03-11T14:23:35.122+0000] {task_command.py:410} INFO - Running <TaskInstance: csv_etl_pipeline.wait_for_file manual__2025-03-11T14:23:32.722483+00:00 [running]> on host 72a7cd2d8042
[2025-03-11T14:23:35.316+0000] {taskinstance.py:1547} INFO - Exporting env vars: AIRFLOW_CTX_DAG_OWNER='***' AIRFLOW_CTX_DAG_ID='csv_etl_pipeline' AIRFLOW_CTX_TASK_ID='wait_for_file' AIRFLOW_CTX_EXECUTION_DATE='2025-03-11T14:23:32.722483+00:00' AIRFLOW_CTX_TRY_NUMBER='1' AIRFLOW_CTX_DAG_RUN_ID='manual__2025-03-11T14:23:32.722483+00:00'
[2025-03-11T14:23:35.348+0000] {base.py:73} INFO - Using connection ID 'fs_default' for task execution.
[2025-03-11T14:23:35.348+0000] {filesystem.py:64} INFO - Poking for file /opt/***/dags/data/Vente.csv
[2025-03-11T14:23:35.349+0000] {taskinstance.py:1824} ERROR - Task failed with exception
Traceback (most recent call last):
  File "/home/airflow/.local/lib/python3.7/site-packages/airflow/sensors/base.py", line 242, in execute
    raise AirflowSensorTimeout(message)
airflow.exceptions.AirflowSensorTimeout: Sensor has timed out; run duration of 0.013694 seconds exceeds the specified timeout of 0.
[2025-03-11T14:23:35.361+0000] {taskinstance.py:1350} INFO - Immediate failure requested. Marking task as FAILED. dag_id=csv_etl_pipeline, task_id=wait_for_file, execution_date=20250311T142332, start_date=20250311T142334, end_date=20250311T142335
[2025-03-11T14:23:35.392+0000] {standard_task_runner.py:109} ERROR - Failed to execute job 126 for task wait_for_file (Sensor has timed out; run duration of 0.013694 seconds exceeds the specified timeout of 0.; 1470)
[2025-03-11T14:23:35.434+0000] {local_task_job_runner.py:225} INFO - Task exited with return code 1
[2025-03-11T14:23:35.477+0000] {taskinstance.py:2651} INFO - 0 downstream tasks scheduled from follow-on schedule check
