[2025-05-05T12:04:55.953+0000] {taskinstance.py:1103} INFO - Dependencies all met for dep_context=non-requeueable deps ti=<TaskInstance: csv_etl_pipeline.load_task manual__2025-05-05T12:04:50.739941+00:00 [queued]>
[2025-05-05T12:04:55.968+0000] {taskinstance.py:1103} INFO - Dependencies all met for dep_context=requeueable deps ti=<TaskInstance: csv_etl_pipeline.load_task manual__2025-05-05T12:04:50.739941+00:00 [queued]>
[2025-05-05T12:04:55.969+0000] {taskinstance.py:1308} INFO - Starting attempt 1 of 1
[2025-05-05T12:04:55.989+0000] {taskinstance.py:1327} INFO - Executing <Task(PythonOperator): load_task> on 2025-05-05 12:04:50.739941+00:00
[2025-05-05T12:04:56.001+0000] {standard_task_runner.py:57} INFO - Started process 1569 to run task
[2025-05-05T12:04:56.008+0000] {standard_task_runner.py:84} INFO - Running: ['***', 'tasks', 'run', 'csv_etl_pipeline', 'load_task', 'manual__2025-05-05T12:04:50.739941+00:00', '--job-id', '47', '--raw', '--subdir', 'DAGS_FOLDER/etl.py', '--cfg-path', '/tmp/tmplxptze2a']
[2025-05-05T12:04:56.009+0000] {standard_task_runner.py:85} INFO - Job 47: Subtask load_task
[2025-05-05T12:04:56.086+0000] {task_command.py:410} INFO - Running <TaskInstance: csv_etl_pipeline.load_task manual__2025-05-05T12:04:50.739941+00:00 [running]> on host c0cf4c6c1505
[2025-05-05T12:04:56.227+0000] {taskinstance.py:1547} INFO - Exporting env vars: AIRFLOW_CTX_DAG_OWNER='***' AIRFLOW_CTX_DAG_ID='csv_etl_pipeline' AIRFLOW_CTX_TASK_ID='load_task' AIRFLOW_CTX_EXECUTION_DATE='2025-05-05T12:04:50.739941+00:00' AIRFLOW_CTX_TRY_NUMBER='1' AIRFLOW_CTX_DAG_RUN_ID='manual__2025-05-05T12:04:50.739941+00:00'
[2025-05-05T12:04:57.015+0000] {taskinstance.py:1824} ERROR - Task failed with exception
Traceback (most recent call last):
  File "/home/airflow/.local/lib/python3.7/site-packages/pandas/core/indexes/base.py", line 3361, in get_loc
    return self._engine.get_loc(casted_key)
  File "pandas/_libs/index.pyx", line 76, in pandas._libs.index.IndexEngine.get_loc
  File "pandas/_libs/index.pyx", line 108, in pandas._libs.index.IndexEngine.get_loc
  File "pandas/_libs/hashtable_class_helper.pxi", line 5198, in pandas._libs.hashtable.PyObjectHashTable.get_item
  File "pandas/_libs/hashtable_class_helper.pxi", line 5206, in pandas._libs.hashtable.PyObjectHashTable.get_item
KeyError: 'Id_vente'

The above exception was the direct cause of the following exception:

Traceback (most recent call last):
  File "/home/airflow/.local/lib/python3.7/site-packages/airflow/operators/python.py", line 181, in execute
    return_value = self.execute_callable()
  File "/home/airflow/.local/lib/python3.7/site-packages/airflow/operators/python.py", line 198, in execute_callable
    return self.python_callable(*self.op_args, **self.op_kwargs)
  File "/opt/airflow/dags/etl.py", line 38, in load_data
    df_new = df[~df['Id_vente'].isin(existing_ids['Id_vente'])]
  File "/home/airflow/.local/lib/python3.7/site-packages/pandas/core/frame.py", line 3458, in __getitem__
    indexer = self.columns.get_loc(key)
  File "/home/airflow/.local/lib/python3.7/site-packages/pandas/core/indexes/base.py", line 3363, in get_loc
    raise KeyError(key) from err
KeyError: 'Id_vente'
[2025-05-05T12:04:57.033+0000] {taskinstance.py:1350} INFO - Marking task as FAILED. dag_id=csv_etl_pipeline, task_id=load_task, execution_date=20250505T120450, start_date=20250505T120455, end_date=20250505T120457
[2025-05-05T12:04:57.049+0000] {standard_task_runner.py:109} ERROR - Failed to execute job 47 for task load_task ('Id_vente'; 1569)
[2025-05-05T12:04:57.103+0000] {local_task_job_runner.py:225} INFO - Task exited with return code 1
[2025-05-05T12:04:57.125+0000] {taskinstance.py:2651} INFO - 0 downstream tasks scheduled from follow-on schedule check
