[2025-03-11T10:52:39.667+0000] {taskinstance.py:1103} INFO - Dependencies all met for dep_context=non-requeueable deps ti=<TaskInstance: csv_etl_pipeline.load_task manual__2025-03-11T10:52:33.955787+00:00 [queued]>
[2025-03-11T10:52:39.677+0000] {taskinstance.py:1103} INFO - Dependencies all met for dep_context=requeueable deps ti=<TaskInstance: csv_etl_pipeline.load_task manual__2025-03-11T10:52:33.955787+00:00 [queued]>
[2025-03-11T10:52:39.677+0000] {taskinstance.py:1308} INFO - Starting attempt 1 of 1
[2025-03-11T10:52:39.691+0000] {taskinstance.py:1327} INFO - Executing <Task(PythonOperator): load_task> on 2025-03-11 10:52:33.955787+00:00
[2025-03-11T10:52:39.698+0000] {standard_task_runner.py:57} INFO - Started process 266 to run task
[2025-03-11T10:52:39.702+0000] {standard_task_runner.py:84} INFO - Running: ['***', 'tasks', 'run', 'csv_etl_pipeline', 'load_task', 'manual__2025-03-11T10:52:33.955787+00:00', '--job-id', '28', '--raw', '--subdir', 'DAGS_FOLDER/etl.py', '--cfg-path', '/tmp/tmpa6l8hy05']
[2025-03-11T10:52:39.703+0000] {standard_task_runner.py:85} INFO - Job 28: Subtask load_task
[2025-03-11T10:52:39.752+0000] {task_command.py:410} INFO - Running <TaskInstance: csv_etl_pipeline.load_task manual__2025-03-11T10:52:33.955787+00:00 [running]> on host 11da0919092a
[2025-03-11T10:52:39.843+0000] {taskinstance.py:1547} INFO - Exporting env vars: AIRFLOW_CTX_DAG_OWNER='***' AIRFLOW_CTX_DAG_ID='csv_etl_pipeline' AIRFLOW_CTX_TASK_ID='load_task' AIRFLOW_CTX_EXECUTION_DATE='2025-03-11T10:52:33.955787+00:00' AIRFLOW_CTX_TRY_NUMBER='1' AIRFLOW_CTX_DAG_RUN_ID='manual__2025-03-11T10:52:33.955787+00:00'
[2025-03-11T10:52:40.017+0000] {taskinstance.py:1824} ERROR - Task failed with exception
Traceback (most recent call last):
  File "/home/airflow/.local/lib/python3.7/site-packages/airflow/operators/python.py", line 181, in execute
    return_value = self.execute_callable()
  File "/home/airflow/.local/lib/python3.7/site-packages/airflow/operators/python.py", line 198, in execute_callable
    return self.python_callable(*self.op_args, **self.op_kwargs)
  File "/opt/airflow/dags/etl.py", line 37, in load_data
    df.to_csv(OUTPUT_CSV, index=False)
  File "/home/airflow/.local/lib/python3.7/site-packages/pandas/core/generic.py", line 3482, in to_csv
    storage_options=storage_options,
  File "/home/airflow/.local/lib/python3.7/site-packages/pandas/io/formats/format.py", line 1105, in to_csv
    csv_formatter.save()
  File "/home/airflow/.local/lib/python3.7/site-packages/pandas/io/formats/csvs.py", line 243, in save
    storage_options=self.storage_options,
  File "/home/airflow/.local/lib/python3.7/site-packages/pandas/io/common.py", line 707, in get_handle
    newline="",
PermissionError: [Errno 13] Permission denied: '/opt/airflow/dags/data/output_data.csv'
[2025-03-11T10:52:40.028+0000] {taskinstance.py:1350} INFO - Marking task as FAILED. dag_id=csv_etl_pipeline, task_id=load_task, execution_date=20250311T105233, start_date=20250311T105239, end_date=20250311T105240
[2025-03-11T10:52:40.042+0000] {standard_task_runner.py:109} ERROR - Failed to execute job 28 for task load_task ([Errno 13] Permission denied: '/opt/airflow/dags/data/output_data.csv'; 266)
[2025-03-11T10:52:40.075+0000] {local_task_job_runner.py:225} INFO - Task exited with return code 1
[2025-03-11T10:52:40.093+0000] {taskinstance.py:2651} INFO - 0 downstream tasks scheduled from follow-on schedule check
