[2025-03-11T13:51:34.339+0000] {taskinstance.py:1103} INFO - Dependencies all met for dep_context=non-requeueable deps ti=<TaskInstance: csv_etl_pipeline.load_task manual__2025-03-11T13:51:24.014207+00:00 [queued]>
[2025-03-11T13:51:34.353+0000] {taskinstance.py:1103} INFO - Dependencies all met for dep_context=requeueable deps ti=<TaskInstance: csv_etl_pipeline.load_task manual__2025-03-11T13:51:24.014207+00:00 [queued]>
[2025-03-11T13:51:34.353+0000] {taskinstance.py:1308} INFO - Starting attempt 1 of 1
[2025-03-11T13:51:34.372+0000] {taskinstance.py:1327} INFO - Executing <Task(PythonOperator): load_task> on 2025-03-11 13:51:24.014207+00:00
[2025-03-11T13:51:34.382+0000] {standard_task_runner.py:57} INFO - Started process 746 to run task
[2025-03-11T13:51:34.388+0000] {standard_task_runner.py:84} INFO - Running: ['***', 'tasks', 'run', 'csv_etl_pipeline', 'load_task', 'manual__2025-03-11T13:51:24.014207+00:00', '--job-id', '68', '--raw', '--subdir', 'DAGS_FOLDER/etl.py', '--cfg-path', '/tmp/tmpxdcag414']
[2025-03-11T13:51:34.389+0000] {standard_task_runner.py:85} INFO - Job 68: Subtask load_task
[2025-03-11T13:51:34.453+0000] {task_command.py:410} INFO - Running <TaskInstance: csv_etl_pipeline.load_task manual__2025-03-11T13:51:24.014207+00:00 [running]> on host 72a7cd2d8042
[2025-03-11T13:51:34.564+0000] {taskinstance.py:1547} INFO - Exporting env vars: AIRFLOW_CTX_DAG_OWNER='***' AIRFLOW_CTX_DAG_ID='csv_etl_pipeline' AIRFLOW_CTX_TASK_ID='load_task' AIRFLOW_CTX_EXECUTION_DATE='2025-03-11T13:51:24.014207+00:00' AIRFLOW_CTX_TRY_NUMBER='1' AIRFLOW_CTX_DAG_RUN_ID='manual__2025-03-11T13:51:24.014207+00:00'
[2025-03-11T13:51:34.594+0000] {logging_mixin.py:149} INFO - ✅ Données chargées dans output_data.csv
[2025-03-11T13:51:34.612+0000] {taskinstance.py:1824} ERROR - Task failed with exception
Traceback (most recent call last):
  File "/home/airflow/.local/lib/python3.7/site-packages/airflow/operators/python.py", line 181, in execute
    return_value = self.execute_callable()
  File "/home/airflow/.local/lib/python3.7/site-packages/airflow/operators/python.py", line 198, in execute_callable
    return self.python_callable(*self.op_args, **self.op_kwargs)
  File "/opt/airflow/dags/etl.py", line 84, in load_data
    os.remove(INPUT_CSV)
PermissionError: [Errno 13] Permission denied: '/opt/airflow/dags/data/Vente.csv'
[2025-03-11T13:51:34.621+0000] {taskinstance.py:1350} INFO - Marking task as FAILED. dag_id=csv_etl_pipeline, task_id=load_task, execution_date=20250311T135124, start_date=20250311T135134, end_date=20250311T135134
[2025-03-11T13:51:34.633+0000] {standard_task_runner.py:109} ERROR - Failed to execute job 68 for task load_task ([Errno 13] Permission denied: '/opt/airflow/dags/data/Vente.csv'; 746)
[2025-03-11T13:51:34.679+0000] {local_task_job_runner.py:225} INFO - Task exited with return code 1
[2025-03-11T13:51:34.696+0000] {taskinstance.py:2651} INFO - 0 downstream tasks scheduled from follow-on schedule check
