[2025-05-05T09:21:40.246+0000] {taskinstance.py:1103} INFO - Dependencies all met for dep_context=non-requeueable deps ti=<TaskInstance: csv_etl_pipeline.wait_for_file manual__2025-05-05T09:21:35.566958+00:00 [queued]>
[2025-05-05T09:21:40.272+0000] {taskinstance.py:1103} INFO - Dependencies all met for dep_context=requeueable deps ti=<TaskInstance: csv_etl_pipeline.wait_for_file manual__2025-05-05T09:21:35.566958+00:00 [queued]>
[2025-05-05T09:21:40.272+0000] {taskinstance.py:1308} INFO - Starting attempt 1 of 1
[2025-05-05T09:21:40.306+0000] {taskinstance.py:1327} INFO - Executing <Task(FileSensor): wait_for_file> on 2025-05-05 09:21:35.566958+00:00
[2025-05-05T09:21:40.319+0000] {standard_task_runner.py:57} INFO - Started process 106 to run task
[2025-05-05T09:21:40.327+0000] {standard_task_runner.py:84} INFO - Running: ['***', 'tasks', 'run', 'csv_etl_pipeline', 'wait_for_file', 'manual__2025-05-05T09:21:35.566958+00:00', '--job-id', '3', '--raw', '--subdir', 'DAGS_FOLDER/etl.py', '--cfg-path', '/tmp/tmp3nhjffj7']
[2025-05-05T09:21:40.328+0000] {standard_task_runner.py:85} INFO - Job 3: Subtask wait_for_file
[2025-05-05T09:21:40.420+0000] {task_command.py:410} INFO - Running <TaskInstance: csv_etl_pipeline.wait_for_file manual__2025-05-05T09:21:35.566958+00:00 [running]> on host 679980e1d605
[2025-05-05T09:21:40.584+0000] {taskinstance.py:1547} INFO - Exporting env vars: AIRFLOW_CTX_DAG_OWNER='***' AIRFLOW_CTX_DAG_ID='csv_etl_pipeline' AIRFLOW_CTX_TASK_ID='wait_for_file' AIRFLOW_CTX_EXECUTION_DATE='2025-05-05T09:21:35.566958+00:00' AIRFLOW_CTX_TRY_NUMBER='1' AIRFLOW_CTX_DAG_RUN_ID='manual__2025-05-05T09:21:35.566958+00:00'
[2025-05-05T09:21:40.646+0000] {taskinstance.py:1824} ERROR - Task failed with exception
Traceback (most recent call last):
  File "/home/airflow/.local/lib/python3.7/site-packages/airflow/sensors/base.py", line 225, in execute
    raise e
  File "/home/airflow/.local/lib/python3.7/site-packages/airflow/sensors/base.py", line 212, in execute
    poke_return = self.poke(context)
  File "/home/airflow/.local/lib/python3.7/site-packages/airflow/sensors/filesystem.py", line 61, in poke
    hook = FSHook(self.fs_conn_id)
  File "/home/airflow/.local/lib/python3.7/site-packages/airflow/hooks/filesystem.py", line 38, in __init__
    conn = self.get_connection(conn_id)
  File "/home/airflow/.local/lib/python3.7/site-packages/airflow/hooks/base.py", line 72, in get_connection
    conn = Connection.get_connection_from_secrets(conn_id)
  File "/home/airflow/.local/lib/python3.7/site-packages/airflow/models/connection.py", line 434, in get_connection_from_secrets
    raise AirflowNotFoundException(f"The conn_id `{conn_id}` isn't defined")
airflow.exceptions.AirflowNotFoundException: The conn_id `fs_default` isn't defined
[2025-05-05T09:21:40.654+0000] {taskinstance.py:1350} INFO - Marking task as FAILED. dag_id=csv_etl_pipeline, task_id=wait_for_file, execution_date=20250505T092135, start_date=20250505T092140, end_date=20250505T092140
[2025-05-05T09:21:40.679+0000] {standard_task_runner.py:109} ERROR - Failed to execute job 3 for task wait_for_file (The conn_id `fs_default` isn't defined; 106)
[2025-05-05T09:21:40.697+0000] {local_task_job_runner.py:225} INFO - Task exited with return code 1
[2025-05-05T09:21:40.773+0000] {taskinstance.py:2651} INFO - 0 downstream tasks scheduled from follow-on schedule check
