[2025-03-11T10:47:05.716+0000] {taskinstance.py:1103} INFO - Dependencies all met for dep_context=non-requeueable deps ti=<TaskInstance: csv_etl_pipeline.transform_task manual__2025-03-11T10:47:01.020298+00:00 [queued]>
[2025-03-11T10:47:05.875+0000] {taskinstance.py:1103} INFO - Dependencies all met for dep_context=requeueable deps ti=<TaskInstance: csv_etl_pipeline.transform_task manual__2025-03-11T10:47:01.020298+00:00 [queued]>
[2025-03-11T10:47:05.875+0000] {taskinstance.py:1308} INFO - Starting attempt 1 of 1
[2025-03-11T10:47:05.888+0000] {taskinstance.py:1327} INFO - Executing <Task(PythonOperator): transform_task> on 2025-03-11 10:47:01.020298+00:00
[2025-03-11T10:47:05.895+0000] {standard_task_runner.py:57} INFO - Started process 149 to run task
[2025-03-11T10:47:05.898+0000] {standard_task_runner.py:84} INFO - Running: ['***', 'tasks', 'run', 'csv_etl_pipeline', 'transform_task', 'manual__2025-03-11T10:47:01.020298+00:00', '--job-id', '19', '--raw', '--subdir', 'DAGS_FOLDER/etl.py', '--cfg-path', '/tmp/tmp35drn2pp']
[2025-03-11T10:47:05.899+0000] {standard_task_runner.py:85} INFO - Job 19: Subtask transform_task
[2025-03-11T10:47:05.961+0000] {task_command.py:410} INFO - Running <TaskInstance: csv_etl_pipeline.transform_task manual__2025-03-11T10:47:01.020298+00:00 [running]> on host 11da0919092a
[2025-03-11T10:47:06.057+0000] {taskinstance.py:1547} INFO - Exporting env vars: AIRFLOW_CTX_DAG_OWNER='***' AIRFLOW_CTX_DAG_ID='csv_etl_pipeline' AIRFLOW_CTX_TASK_ID='transform_task' AIRFLOW_CTX_EXECUTION_DATE='2025-03-11T10:47:01.020298+00:00' AIRFLOW_CTX_TRY_NUMBER='1' AIRFLOW_CTX_DAG_RUN_ID='manual__2025-03-11T10:47:01.020298+00:00'
[2025-03-11T10:47:06.266+0000] {taskinstance.py:1824} ERROR - Task failed with exception
Traceback (most recent call last):
  File "/home/airflow/.local/lib/python3.7/site-packages/airflow/operators/python.py", line 181, in execute
    return_value = self.execute_callable()
  File "/home/airflow/.local/lib/python3.7/site-packages/airflow/operators/python.py", line 198, in execute_callable
    return self.python_callable(*self.op_args, **self.op_kwargs)
  File "/opt/airflow/dags/etl.py", line 25, in transform_data
    df["Valeur"] = df["Valeur"].astype(float)
  File "/home/airflow/.local/lib/python3.7/site-packages/pandas/core/generic.py", line 5815, in astype
    new_data = self._mgr.astype(dtype=dtype, copy=copy, errors=errors)
  File "/home/airflow/.local/lib/python3.7/site-packages/pandas/core/internals/managers.py", line 418, in astype
    return self.apply("astype", dtype=dtype, copy=copy, errors=errors)
  File "/home/airflow/.local/lib/python3.7/site-packages/pandas/core/internals/managers.py", line 327, in apply
    applied = getattr(b, f)(**kwargs)
  File "/home/airflow/.local/lib/python3.7/site-packages/pandas/core/internals/blocks.py", line 591, in astype
    new_values = astype_array_safe(values, dtype, copy=copy, errors=errors)
  File "/home/airflow/.local/lib/python3.7/site-packages/pandas/core/dtypes/cast.py", line 1309, in astype_array_safe
    new_values = astype_array(values, dtype, copy=copy)
  File "/home/airflow/.local/lib/python3.7/site-packages/pandas/core/dtypes/cast.py", line 1257, in astype_array
    values = astype_nansafe(values, dtype, copy=copy)
  File "/home/airflow/.local/lib/python3.7/site-packages/pandas/core/dtypes/cast.py", line 1201, in astype_nansafe
    return arr.astype(dtype, copy=True)
ValueError: could not convert string to float: '189598,58'
[2025-03-11T10:47:06.279+0000] {taskinstance.py:1350} INFO - Marking task as FAILED. dag_id=csv_etl_pipeline, task_id=transform_task, execution_date=20250311T104701, start_date=20250311T104705, end_date=20250311T104706
[2025-03-11T10:47:06.297+0000] {standard_task_runner.py:109} ERROR - Failed to execute job 19 for task transform_task (could not convert string to float: '189598,58'; 149)
[2025-03-11T10:47:06.312+0000] {local_task_job_runner.py:225} INFO - Task exited with return code 1
[2025-03-11T10:47:06.343+0000] {taskinstance.py:2651} INFO - 0 downstream tasks scheduled from follow-on schedule check
